{
  "comments": [
    {
      "key": {
        "uuid": "13f289da_6a8fd342",
        "filename": "tools/releasetools/merge_target_files.py",
        "patchSetId": 2
      },
      "lineNbr": 671,
      "author": {
        "id": 1395887
      },
      "writtenOn": "2019-04-15T20:40:24Z",
      "side": 1,
      "message": "It seems like a lot of the release tools like to raise ValueError for situations like this. For consistency, follow the same approach?",
      "range": {
        "startLine": 671,
        "startChar": 6,
        "endLine": 671,
        "endChar": 17
      },
      "revId": "1dce6ec5da1e2af10c9d560ae8d28ae9bb0816dc",
      "serverId": "85c56323-6fa9-3386-8a01-6480fb634889",
      "unresolved": true
    },
    {
      "key": {
        "uuid": "81571fe6_2f50cf54",
        "filename": "tools/releasetools/merge_target_files.py",
        "patchSetId": 2
      },
      "lineNbr": 671,
      "author": {
        "id": 1455782
      },
      "writtenOn": "2019-04-15T21:20:19Z",
      "side": 1,
      "message": "Raised common.ExternalError like we already do in this script elsewhere (other scripts raise this error type too).",
      "parentUuid": "13f289da_6a8fd342",
      "range": {
        "startLine": 671,
        "startChar": 6,
        "endLine": 671,
        "endChar": 17
      },
      "revId": "1dce6ec5da1e2af10c9d560ae8d28ae9bb0816dc",
      "serverId": "85c56323-6fa9-3386-8a01-6480fb634889",
      "unresolved": true
    },
    {
      "key": {
        "uuid": "b34dc902_ba705e6c",
        "filename": "tools/releasetools/merge_target_files.py",
        "patchSetId": 2
      },
      "lineNbr": 671,
      "author": {
        "id": 1395887
      },
      "writtenOn": "2019-04-15T21:39:40Z",
      "side": 1,
      "message": "In common.py, it seems like ExternalError is (mostly) used to convey that a subprocess failed. On the other hand, ValueError is sometimes used in cases like this case. For example: https://android.googlesource.com/platform/build/+/8a66a71b06c62ba73953262b52ac45a2920df8af/tools/releasetools/common.py#325",
      "parentUuid": "81571fe6_2f50cf54",
      "range": {
        "startLine": 671,
        "startChar": 6,
        "endLine": 671,
        "endChar": 17
      },
      "revId": "1dce6ec5da1e2af10c9d560ae8d28ae9bb0816dc",
      "serverId": "85c56323-6fa9-3386-8a01-6480fb634889",
      "unresolved": true
    },
    {
      "key": {
        "uuid": "7cfe1669_42be1718",
        "filename": "tools/releasetools/merge_target_files.py",
        "patchSetId": 2
      },
      "lineNbr": 671,
      "author": {
        "id": 1455782
      },
      "writtenOn": "2019-04-15T21:56:20Z",
      "side": 1,
      "message": "Ah makes sense. Thanks for doing the research. Changed this one \u0026 the other to use ValueError.",
      "parentUuid": "b34dc902_ba705e6c",
      "range": {
        "startLine": 671,
        "startChar": 6,
        "endLine": 671,
        "endChar": 17
      },
      "revId": "1dce6ec5da1e2af10c9d560ae8d28ae9bb0816dc",
      "serverId": "85c56323-6fa9-3386-8a01-6480fb634889",
      "unresolved": true
    }
  ]
}